2021-03-24 20:56:15,160 (88425/MainThread) litecli.main ERROR - sql: 'syntax_style default;', error: OperationalError('near "syntax_style": syntax error')
2021-03-24 20:56:15,160 (88425/MainThread) litecli.main ERROR - traceback: 'Traceback (most recent call last):\n  File "/usr/local/Cellar/litecli/1.0.0/libexec/lib/python3.9/site-packages/litecli/sqlexecute.py", line 116, in run\n    for result in special.execute(cur, sql):\n  File "/usr/local/Cellar/litecli/1.0.0/libexec/lib/python3.9/site-packages/litecli/packages/special/main.py", line 104, in execute\n    raise CommandNotFound\nlitecli.packages.special.main.CommandNotFound\n\nDuring handling of the above exception, another exception occurred:\n\nTraceback (most recent call last):\n  File "/usr/local/Cellar/litecli/1.0.0/libexec/lib/python3.9/site-packages/litecli/main.py", line 440, in one_iteration\n    for title, cur, headers, status in res:\n  File "/usr/local/Cellar/litecli/1.0.0/libexec/lib/python3.9/site-packages/litecli/sqlexecute.py", line 120, in run\n    cur.execute(sql)\nsqlite3.OperationalError: near "syntax_style": syntax error\n'
2021-03-24 20:56:51,441 (88525/MainThread) litecli.main ERROR - sql: 'INSERT INTO todo(title, content) VALUES ("title-3", "content-3");', error: IntegrityError('UNIQUE constraint failed: todo.title')
2021-03-24 20:56:51,442 (88525/MainThread) litecli.main ERROR - traceback: 'Traceback (most recent call last):\n  File "/usr/local/Cellar/litecli/1.0.0/libexec/lib/python3.9/site-packages/litecli/sqlexecute.py", line 116, in run\n    for result in special.execute(cur, sql):\n  File "/usr/local/Cellar/litecli/1.0.0/libexec/lib/python3.9/site-packages/litecli/packages/special/main.py", line 104, in execute\n    raise CommandNotFound\nlitecli.packages.special.main.CommandNotFound\n\nDuring handling of the above exception, another exception occurred:\n\nTraceback (most recent call last):\n  File "/usr/local/Cellar/litecli/1.0.0/libexec/lib/python3.9/site-packages/litecli/main.py", line 440, in one_iteration\n    for title, cur, headers, status in res:\n  File "/usr/local/Cellar/litecli/1.0.0/libexec/lib/python3.9/site-packages/litecli/sqlexecute.py", line 120, in run\n    cur.execute(sql)\nsqlite3.IntegrityError: UNIQUE constraint failed: todo.title\n'
2021-03-24 20:59:38,791 (88595/MainThread) litecli.main ERROR - sql: 'INSERT INTO todo(title, content) VALUES ("title-3", "content-3");', error: IntegrityError('UNIQUE constraint failed: todo.title')
2021-03-24 20:59:38,792 (88595/MainThread) litecli.main ERROR - traceback: 'Traceback (most recent call last):\n  File "/usr/local/Cellar/litecli/1.0.0/libexec/lib/python3.9/site-packages/litecli/sqlexecute.py", line 116, in run\n    for result in special.execute(cur, sql):\n  File "/usr/local/Cellar/litecli/1.0.0/libexec/lib/python3.9/site-packages/litecli/packages/special/main.py", line 104, in execute\n    raise CommandNotFound\nlitecli.packages.special.main.CommandNotFound\n\nDuring handling of the above exception, another exception occurred:\n\nTraceback (most recent call last):\n  File "/usr/local/Cellar/litecli/1.0.0/libexec/lib/python3.9/site-packages/litecli/main.py", line 440, in one_iteration\n    for title, cur, headers, status in res:\n  File "/usr/local/Cellar/litecli/1.0.0/libexec/lib/python3.9/site-packages/litecli/sqlexecute.py", line 120, in run\n    cur.execute(sql)\nsqlite3.IntegrityError: UNIQUE constraint failed: todo.title\n'
2021-03-25 22:19:16,104 (94305/MainThread) litecli.main ERROR - sql: 'WITH todo_with_tags_string(todo_id, todo_title, todo_tag_string) AS (\n    SELECT\n        todo.id as todo_id,\n        todo.title as todo_title,\n        " " || group_concat(tag.name, " ") || " " AS todo_tag_string -- " " isn\'t allowed in tags\n    FROM todo\n        JOIN todo_tag ON todo.id = todo_tag.todo_id\n        JOIN tag ON todo_tag.tag_id = tag.id\n    GROUP BY todo_id\n)\n    SELECT todo_id, todo_title, todo_url, todo_tag_string FROM todo_with_tags_string\n    UNION ALL\n    SELECT\n        todo.id as todo_id,\n        todo.title as todo_title,\n        \'\'\n    FROM todo\n    WHERE todo_id NOT IN (\n        SELECT todo_id FROM todo_with_tags_string\n    )\n;', error: OperationalError('no such column: todo_url')
2021-03-25 22:19:16,109 (94305/MainThread) litecli.main ERROR - traceback: 'Traceback (most recent call last):\n  File "/usr/local/Cellar/litecli/1.0.0/libexec/lib/python3.9/site-packages/litecli/sqlexecute.py", line 116, in run\n    for result in special.execute(cur, sql):\n  File "/usr/local/Cellar/litecli/1.0.0/libexec/lib/python3.9/site-packages/litecli/packages/special/main.py", line 104, in execute\n    raise CommandNotFound\nlitecli.packages.special.main.CommandNotFound\n\nDuring handling of the above exception, another exception occurred:\n\nTraceback (most recent call last):\n  File "/usr/local/Cellar/litecli/1.0.0/libexec/lib/python3.9/site-packages/litecli/main.py", line 440, in one_iteration\n    for title, cur, headers, status in res:\n  File "/usr/local/Cellar/litecli/1.0.0/libexec/lib/python3.9/site-packages/litecli/sqlexecute.py", line 120, in run\n    cur.execute(sql)\nsqlite3.OperationalError: no such column: todo_url\n'
2021-03-25 23:38:49,711 (99514/MainThread) litecli.main ERROR - sql: 'SELECT 1, x FROM x IN (1,2,3);', error: OperationalError('near "IN": syntax error')
2021-03-25 23:38:49,712 (99514/MainThread) litecli.main ERROR - traceback: 'Traceback (most recent call last):\n  File "/usr/local/Cellar/litecli/1.0.0/libexec/lib/python3.9/site-packages/litecli/sqlexecute.py", line 116, in run\n    for result in special.execute(cur, sql):\n  File "/usr/local/Cellar/litecli/1.0.0/libexec/lib/python3.9/site-packages/litecli/packages/special/main.py", line 104, in execute\n    raise CommandNotFound\nlitecli.packages.special.main.CommandNotFound\n\nDuring handling of the above exception, another exception occurred:\n\nTraceback (most recent call last):\n  File "/usr/local/Cellar/litecli/1.0.0/libexec/lib/python3.9/site-packages/litecli/main.py", line 440, in one_iteration\n    for title, cur, headers, status in res:\n  File "/usr/local/Cellar/litecli/1.0.0/libexec/lib/python3.9/site-packages/litecli/sqlexecute.py", line 120, in run\n    cur.execute(sql)\nsqlite3.OperationalError: near "IN": syntax error\n'
2021-03-25 23:39:07,614 (99514/MainThread) litecli.main ERROR - sql: 'SELECT FROM (1,2,3);', error: OperationalError('near "FROM": syntax error')
2021-03-25 23:39:07,615 (99514/MainThread) litecli.main ERROR - traceback: 'Traceback (most recent call last):\n  File "/usr/local/Cellar/litecli/1.0.0/libexec/lib/python3.9/site-packages/litecli/sqlexecute.py", line 116, in run\n    for result in special.execute(cur, sql):\n  File "/usr/local/Cellar/litecli/1.0.0/libexec/lib/python3.9/site-packages/litecli/packages/special/main.py", line 104, in execute\n    raise CommandNotFound\nlitecli.packages.special.main.CommandNotFound\n\nDuring handling of the above exception, another exception occurred:\n\nTraceback (most recent call last):\n  File "/usr/local/Cellar/litecli/1.0.0/libexec/lib/python3.9/site-packages/litecli/main.py", line 440, in one_iteration\n    for title, cur, headers, status in res:\n  File "/usr/local/Cellar/litecli/1.0.0/libexec/lib/python3.9/site-packages/litecli/sqlexecute.py", line 120, in run\n    cur.execute(sql)\nsqlite3.OperationalError: near "FROM": syntax error\n'
2021-03-25 23:39:12,686 (99514/MainThread) litecli.main ERROR - sql: 'SELECT  (1,2,3);', error: OperationalError('row value misused')
2021-03-25 23:39:12,687 (99514/MainThread) litecli.main ERROR - traceback: 'Traceback (most recent call last):\n  File "/usr/local/Cellar/litecli/1.0.0/libexec/lib/python3.9/site-packages/litecli/sqlexecute.py", line 116, in run\n    for result in special.execute(cur, sql):\n  File "/usr/local/Cellar/litecli/1.0.0/libexec/lib/python3.9/site-packages/litecli/packages/special/main.py", line 104, in execute\n    raise CommandNotFound\nlitecli.packages.special.main.CommandNotFound\n\nDuring handling of the above exception, another exception occurred:\n\nTraceback (most recent call last):\n  File "/usr/local/Cellar/litecli/1.0.0/libexec/lib/python3.9/site-packages/litecli/main.py", line 440, in one_iteration\n    for title, cur, headers, status in res:\n  File "/usr/local/Cellar/litecli/1.0.0/libexec/lib/python3.9/site-packages/litecli/sqlexecute.py", line 120, in run\n    cur.execute(sql)\nsqlite3.OperationalError: row value misused\n'
2021-03-25 23:42:13,264 (99514/MainThread) litecli.main ERROR - sql: 'SELECT x FROM (VALUES (1),(2)) as mytable(x));', error: OperationalError('near "(": syntax error')
2021-03-25 23:42:13,265 (99514/MainThread) litecli.main ERROR - traceback: 'Traceback (most recent call last):\n  File "/usr/local/Cellar/litecli/1.0.0/libexec/lib/python3.9/site-packages/litecli/sqlexecute.py", line 116, in run\n    for result in special.execute(cur, sql):\n  File "/usr/local/Cellar/litecli/1.0.0/libexec/lib/python3.9/site-packages/litecli/packages/special/main.py", line 104, in execute\n    raise CommandNotFound\nlitecli.packages.special.main.CommandNotFound\n\nDuring handling of the above exception, another exception occurred:\n\nTraceback (most recent call last):\n  File "/usr/local/Cellar/litecli/1.0.0/libexec/lib/python3.9/site-packages/litecli/main.py", line 440, in one_iteration\n    for title, cur, headers, status in res:\n  File "/usr/local/Cellar/litecli/1.0.0/libexec/lib/python3.9/site-packages/litecli/sqlexecute.py", line 120, in run\n    cur.execute(sql)\nsqlite3.OperationalError: near "(": syntax error\n'
2021-03-25 23:42:15,400 (99514/MainThread) litecli.main ERROR - sql: 'SELECT x FROM (VALUES (1),(2)) as mytable(x);', error: OperationalError('near "(": syntax error')
2021-03-25 23:42:15,400 (99514/MainThread) litecli.main ERROR - traceback: 'Traceback (most recent call last):\n  File "/usr/local/Cellar/litecli/1.0.0/libexec/lib/python3.9/site-packages/litecli/sqlexecute.py", line 116, in run\n    for result in special.execute(cur, sql):\n  File "/usr/local/Cellar/litecli/1.0.0/libexec/lib/python3.9/site-packages/litecli/packages/special/main.py", line 104, in execute\n    raise CommandNotFound\nlitecli.packages.special.main.CommandNotFound\n\nDuring handling of the above exception, another exception occurred:\n\nTraceback (most recent call last):\n  File "/usr/local/Cellar/litecli/1.0.0/libexec/lib/python3.9/site-packages/litecli/main.py", line 440, in one_iteration\n    for title, cur, headers, status in res:\n  File "/usr/local/Cellar/litecli/1.0.0/libexec/lib/python3.9/site-packages/litecli/sqlexecute.py", line 120, in run\n    cur.execute(sql)\nsqlite3.OperationalError: near "(": syntax error\n'
2021-03-25 23:43:45,382 (99514/MainThread) litecli.main ERROR - sql: "select col1, 128 col2, 13 col3, 1 col4\nfrom ( values ('AD'), ('AE'), ('AF'), ('AG'), ('AI'), ('AL'), ('AM')) as x (col1)\n;", error: OperationalError('near "(": syntax error')
2021-03-25 23:43:45,382 (99514/MainThread) litecli.main ERROR - traceback: 'Traceback (most recent call last):\n  File "/usr/local/Cellar/litecli/1.0.0/libexec/lib/python3.9/site-packages/litecli/sqlexecute.py", line 116, in run\n    for result in special.execute(cur, sql):\n  File "/usr/local/Cellar/litecli/1.0.0/libexec/lib/python3.9/site-packages/litecli/packages/special/main.py", line 104, in execute\n    raise CommandNotFound\nlitecli.packages.special.main.CommandNotFound\n\nDuring handling of the above exception, another exception occurred:\n\nTraceback (most recent call last):\n  File "/usr/local/Cellar/litecli/1.0.0/libexec/lib/python3.9/site-packages/litecli/main.py", line 440, in one_iteration\n    for title, cur, headers, status in res:\n  File "/usr/local/Cellar/litecli/1.0.0/libexec/lib/python3.9/site-packages/litecli/sqlexecute.py", line 120, in run\n    cur.execute(sql)\nsqlite3.OperationalError: near "(": syntax error\n'
2021-03-25 23:45:05,389 (99514/MainThread) litecli.main ERROR - sql: "select col1, 128 col2, 13 col3, 1 col4\nfrom ( values ('AD'), ('AE'), ('AF'), ('AG'), ('AI'), ('AL'), ('AM'));\n;", error: OperationalError('no such column: col1')
2021-03-25 23:45:05,389 (99514/MainThread) litecli.main ERROR - traceback: 'Traceback (most recent call last):\n  File "/usr/local/Cellar/litecli/1.0.0/libexec/lib/python3.9/site-packages/litecli/sqlexecute.py", line 116, in run\n    for result in special.execute(cur, sql):\n  File "/usr/local/Cellar/litecli/1.0.0/libexec/lib/python3.9/site-packages/litecli/packages/special/main.py", line 104, in execute\n    raise CommandNotFound\nlitecli.packages.special.main.CommandNotFound\n\nDuring handling of the above exception, another exception occurred:\n\nTraceback (most recent call last):\n  File "/usr/local/Cellar/litecli/1.0.0/libexec/lib/python3.9/site-packages/litecli/main.py", line 440, in one_iteration\n    for title, cur, headers, status in res:\n  File "/usr/local/Cellar/litecli/1.0.0/libexec/lib/python3.9/site-packages/litecli/sqlexecute.py", line 120, in run\n    cur.execute(sql)\nsqlite3.OperationalError: no such column: col1\n'
2021-03-25 23:45:27,250 (99514/MainThread) litecli.main ERROR - sql: "select col1, 128 col2, 13 col3, 1 col4\nfrom ( values ('AD'), ('AE'), ('AF'), ('AG'), ('AI'), ('AL'), ('AM')) as x (col1);", error: OperationalError('near "(": syntax error')
2021-03-25 23:45:27,250 (99514/MainThread) litecli.main ERROR - traceback: 'Traceback (most recent call last):\n  File "/usr/local/Cellar/litecli/1.0.0/libexec/lib/python3.9/site-packages/litecli/sqlexecute.py", line 116, in run\n    for result in special.execute(cur, sql):\n  File "/usr/local/Cellar/litecli/1.0.0/libexec/lib/python3.9/site-packages/litecli/packages/special/main.py", line 104, in execute\n    raise CommandNotFound\nlitecli.packages.special.main.CommandNotFound\n\nDuring handling of the above exception, another exception occurred:\n\nTraceback (most recent call last):\n  File "/usr/local/Cellar/litecli/1.0.0/libexec/lib/python3.9/site-packages/litecli/main.py", line 440, in one_iteration\n    for title, cur, headers, status in res:\n  File "/usr/local/Cellar/litecli/1.0.0/libexec/lib/python3.9/site-packages/litecli/sqlexecute.py", line 120, in run\n    cur.execute(sql)\nsqlite3.OperationalError: near "(": syntax error\n'
2021-03-25 23:46:26,105 (99514/MainThread) litecli.main ERROR - sql: "( values ('AD'), ('AE'), ('AF'), ('AG'), ('AI'), ('AL'), ('AM'))\n;", error: OperationalError('near "(": syntax error')
2021-03-25 23:46:26,105 (99514/MainThread) litecli.main ERROR - traceback: 'Traceback (most recent call last):\n  File "/usr/local/Cellar/litecli/1.0.0/libexec/lib/python3.9/site-packages/litecli/sqlexecute.py", line 116, in run\n    for result in special.execute(cur, sql):\n  File "/usr/local/Cellar/litecli/1.0.0/libexec/lib/python3.9/site-packages/litecli/packages/special/main.py", line 104, in execute\n    raise CommandNotFound\nlitecli.packages.special.main.CommandNotFound\n\nDuring handling of the above exception, another exception occurred:\n\nTraceback (most recent call last):\n  File "/usr/local/Cellar/litecli/1.0.0/libexec/lib/python3.9/site-packages/litecli/main.py", line 440, in one_iteration\n    for title, cur, headers, status in res:\n  File "/usr/local/Cellar/litecli/1.0.0/libexec/lib/python3.9/site-packages/litecli/sqlexecute.py", line 120, in run\n    cur.execute(sql)\nsqlite3.OperationalError: near "(": syntax error\n'
2021-03-25 23:47:31,968 (99514/MainThread) litecli.main ERROR - sql: 'WITH inserted(id) AS ( VALUES (1 ,2, 3)) SELECT id FROM inserted;', error: OperationalError('table inserted has 3 values for 1 columns')
2021-03-25 23:47:31,968 (99514/MainThread) litecli.main ERROR - traceback: 'Traceback (most recent call last):\n  File "/usr/local/Cellar/litecli/1.0.0/libexec/lib/python3.9/site-packages/litecli/sqlexecute.py", line 116, in run\n    for result in special.execute(cur, sql):\n  File "/usr/local/Cellar/litecli/1.0.0/libexec/lib/python3.9/site-packages/litecli/packages/special/main.py", line 104, in execute\n    raise CommandNotFound\nlitecli.packages.special.main.CommandNotFound\n\nDuring handling of the above exception, another exception occurred:\n\nTraceback (most recent call last):\n  File "/usr/local/Cellar/litecli/1.0.0/libexec/lib/python3.9/site-packages/litecli/main.py", line 440, in one_iteration\n    for title, cur, headers, status in res:\n  File "/usr/local/Cellar/litecli/1.0.0/libexec/lib/python3.9/site-packages/litecli/sqlexecute.py", line 120, in run\n    cur.execute(sql)\nsqlite3.OperationalError: table inserted has 3 values for 1 columns\n'
2021-03-25 23:54:50,893 (99514/MainThread) litecli.main ERROR - sql: 'SELECT id FROM tag WHERE id IN  VALUES (1);', error: OperationalError('near "VALUES": syntax error')
2021-03-25 23:54:50,894 (99514/MainThread) litecli.main ERROR - traceback: 'Traceback (most recent call last):\n  File "/usr/local/Cellar/litecli/1.0.0/libexec/lib/python3.9/site-packages/litecli/sqlexecute.py", line 116, in run\n    for result in special.execute(cur, sql):\n  File "/usr/local/Cellar/litecli/1.0.0/libexec/lib/python3.9/site-packages/litecli/packages/special/main.py", line 104, in execute\n    raise CommandNotFound\nlitecli.packages.special.main.CommandNotFound\n\nDuring handling of the above exception, another exception occurred:\n\nTraceback (most recent call last):\n  File "/usr/local/Cellar/litecli/1.0.0/libexec/lib/python3.9/site-packages/litecli/main.py", line 440, in one_iteration\n    for title, cur, headers, status in res:\n  File "/usr/local/Cellar/litecli/1.0.0/libexec/lib/python3.9/site-packages/litecli/sqlexecute.py", line 120, in run\n    cur.execute(sql)\nsqlite3.OperationalError: near "VALUES": syntax error\n'
2021-03-25 23:58:36,293 (99514/MainThread) litecli.main ERROR - sql: '( VALUES (1));', error: OperationalError('near "(": syntax error')
2021-03-25 23:58:36,294 (99514/MainThread) litecli.main ERROR - traceback: 'Traceback (most recent call last):\n  File "/usr/local/Cellar/litecli/1.0.0/libexec/lib/python3.9/site-packages/litecli/sqlexecute.py", line 116, in run\n    for result in special.execute(cur, sql):\n  File "/usr/local/Cellar/litecli/1.0.0/libexec/lib/python3.9/site-packages/litecli/packages/special/main.py", line 104, in execute\n    raise CommandNotFound\nlitecli.packages.special.main.CommandNotFound\n\nDuring handling of the above exception, another exception occurred:\n\nTraceback (most recent call last):\n  File "/usr/local/Cellar/litecli/1.0.0/libexec/lib/python3.9/site-packages/litecli/main.py", line 440, in one_iteration\n    for title, cur, headers, status in res:\n  File "/usr/local/Cellar/litecli/1.0.0/libexec/lib/python3.9/site-packages/litecli/sqlexecute.py", line 120, in run\n    cur.execute(sql)\nsqlite3.OperationalError: near "(": syntax error\n'
2021-03-25 23:59:32,502 (99514/MainThread) litecli.main ERROR - sql: 'SELECT x FROM ( VALUES (1), (2) );', error: OperationalError('no such column: x')
2021-03-25 23:59:32,503 (99514/MainThread) litecli.main ERROR - traceback: 'Traceback (most recent call last):\n  File "/usr/local/Cellar/litecli/1.0.0/libexec/lib/python3.9/site-packages/litecli/sqlexecute.py", line 116, in run\n    for result in special.execute(cur, sql):\n  File "/usr/local/Cellar/litecli/1.0.0/libexec/lib/python3.9/site-packages/litecli/packages/special/main.py", line 104, in execute\n    raise CommandNotFound\nlitecli.packages.special.main.CommandNotFound\n\nDuring handling of the above exception, another exception occurred:\n\nTraceback (most recent call last):\n  File "/usr/local/Cellar/litecli/1.0.0/libexec/lib/python3.9/site-packages/litecli/main.py", line 440, in one_iteration\n    for title, cur, headers, status in res:\n  File "/usr/local/Cellar/litecli/1.0.0/libexec/lib/python3.9/site-packages/litecli/sqlexecute.py", line 120, in run\n    cur.execute(sql)\nsqlite3.OperationalError: no such column: x\n'
2021-03-25 23:59:52,065 (99514/MainThread) litecli.main ERROR - sql: 'SELECT x FROM ( VALUES (1), (2) ) AS t(x);', error: OperationalError('near "(": syntax error')
2021-03-25 23:59:52,065 (99514/MainThread) litecli.main ERROR - traceback: 'Traceback (most recent call last):\n  File "/usr/local/Cellar/litecli/1.0.0/libexec/lib/python3.9/site-packages/litecli/sqlexecute.py", line 116, in run\n    for result in special.execute(cur, sql):\n  File "/usr/local/Cellar/litecli/1.0.0/libexec/lib/python3.9/site-packages/litecli/packages/special/main.py", line 104, in execute\n    raise CommandNotFound\nlitecli.packages.special.main.CommandNotFound\n\nDuring handling of the above exception, another exception occurred:\n\nTraceback (most recent call last):\n  File "/usr/local/Cellar/litecli/1.0.0/libexec/lib/python3.9/site-packages/litecli/main.py", line 440, in one_iteration\n    for title, cur, headers, status in res:\n  File "/usr/local/Cellar/litecli/1.0.0/libexec/lib/python3.9/site-packages/litecli/sqlexecute.py", line 120, in run\n    cur.execute(sql)\nsqlite3.OperationalError: near "(": syntax error\n'
2021-03-25 23:59:59,183 (99514/MainThread) litecli.main ERROR - sql: 'SELECT t.x FROM ( VALUES (1), (2) ) AS t(x);', error: OperationalError('near "(": syntax error')
2021-03-25 23:59:59,184 (99514/MainThread) litecli.main ERROR - traceback: 'Traceback (most recent call last):\n  File "/usr/local/Cellar/litecli/1.0.0/libexec/lib/python3.9/site-packages/litecli/sqlexecute.py", line 116, in run\n    for result in special.execute(cur, sql):\n  File "/usr/local/Cellar/litecli/1.0.0/libexec/lib/python3.9/site-packages/litecli/packages/special/main.py", line 104, in execute\n    raise CommandNotFound\nlitecli.packages.special.main.CommandNotFound\n\nDuring handling of the above exception, another exception occurred:\n\nTraceback (most recent call last):\n  File "/usr/local/Cellar/litecli/1.0.0/libexec/lib/python3.9/site-packages/litecli/main.py", line 440, in one_iteration\n    for title, cur, headers, status in res:\n  File "/usr/local/Cellar/litecli/1.0.0/libexec/lib/python3.9/site-packages/litecli/sqlexecute.py", line 120, in run\n    cur.execute(sql)\nsqlite3.OperationalError: near "(": syntax error\n'
